Workbook
Name Slicer_Country_Name: #N/A

Sheet Data
A1: Country Name | B1: Country Code | C1: Series Name | D1: Series Code | E1: 2010 [YR2010] | F1: 2011 [YR2011] | G1: 2012 [YR2012] | H1: 2013 [YR2013] | I1: 2014 [YR2014] | J1: 2015 [YR2015] | K1: 2016 [YR2016] | L1: 2017 [YR2017] | M1: 2018 [YR2018] | N1: 2019 [YR2019] | O1: 2020 [YR2020] | P1: 2021 [YR2021] | Q1: 2022 [YR2022] | R1: 2023 [YR2023] | S1: 2024 [YR2024] | T1: 2025 [YR2025]
A2: Pakistan | B2: PAK | C2: GDP (current US$) | D2: NY.GDP.MKTP.CD | E2: 1.9670962e+11 | F2: 2.3058658e+11 | G2: 2.5010697e+11 | H2: 2.5865723e+11 | I2: 2.7139047e+11 | J2: 2.9996359e+11 | K2: 3.1363e+11 | L2: 3.3920553e+11 | M2: 3.5612817e+11 | N2: 3.2090947e+11 | O2: 3.0042561e+11 | P2: 3.4851665e+11 | Q2: 3.748903e+11 | R2: 3.3668635e+11 | S2: 3.7174709e+11 | T2: 4.0730721e+11
A3: Pakistan | B3: PAK | C3: GDP growth (annual %) | D3: NY.GDP.MKTP.KD.ZG | E3: 1.5017175 | F3: 2.6801169 | G3: 3.0275839 | H3: 4.366865 | I3: 4.1164282 | J3: 4.2179421 | K3: 6.5738383 | L3: 4.4326259 | M3: 6.1517026 | N3: 2.4976369 | O3: -1.2740874 | P3: 6.5138858 | Q3: 4.7781069 | R3: -0.414936 | S3: 3.081763 | T3: 3.6984267
A4: Pakistan | B4: PAK | C4: Inflation, consumer prices (annual %) | D4: FP.CPI.TOTL.ZG | E4: 12.938871 | F4: 11.916093 | G4: 9.6823519 | H4: 7.6921561 | I4: 7.189384 | J4: 2.5293282 | K4: 3.7651192 | L4: 4.0853737 | M4: 5.0780573 | N4: 10.578031 | O4: 9.7401162 | P4: 9.4964158 | Q4: 19.87386 | R4: 30.768128 | S4: 12.632532 | T4: 3.5455521
A5: Pakistan | B5: PAK | C5: Unemployment, total (% of total labor force) (modeled ILO estimate) | D5: SL.UEM.TOTL.ZS | E5: 0.653 | F5: 0.796 | G5: 3.667 | H5: 2.954 | I5: 1.827 | J5: 3.566 | K5: 2.285 | L5: 3.204 | M5: 4.083 | N5: 4.83 | O5: 5.994 | P5: 6.338 | Q5: 5.291 | R5: 5.237 | S5: 5.492 | T5: 5.42
A6: Pakistan | B6: PAK | C6: Lending interest rate (%) | D6: FR.INR.LEND | E6: 14.0425 | F6: 14.419167 | G6: 13.519167 | H6: 11.985833 | I6: 11.73 | J6: 10.155833 | K6: 8.755 | L6: 8.21 | M6: 8.5308333 | N6: 12.233055 | O6: 10.757749 | P6: 8.6659742 | Q6: .. | R6: .. | S6: .. | T6: ..
A7: Pakistan | B7: PAK | C7: Official exchange rate (LCU per US$, period average) | D7: PA.NUS.FCRF | E7: 85.193816 | F7: 86.343383 | G7: 93.395197 | H7: 101.6289 | I7: 101.10009 | J7: 102.76927 | K7: 104.76912 | L7: 105.45516 | M7: 121.82407 | N7: 150.03625 | O7: 161.83848 | P7: 162.90625 | Q7: 204.86719 | R7: 280.35611 | S7: 278.58072 | T7: 281.143
A8: Pakistan | B8: PAK | C8: Exports of goods and services (% of GDP) | D8: NE.EXP.GNFS.ZS | E8: 12.637225 | F8: 13.482555 | G8: 11.873964 | H8: 12.177499 | I8: 11.194972 | J8: 9.974571 | K8: 8.7367164 | L8: 8.2216113 | M8: 8.5817996 | N8: 9.3908635 | O8: 9.2985594 | P8: 9.0515999 | Q8: 10.54059 | R8: 10.493959 | S8: 10.385503 | T8: 9.9852067
A9: Pakistan | B9: PAK | C9: Imports of goods and services (% of GDP) | D9: NE.IMP.GNFS.ZS | E9: 19.351777 | F9: 18.880083 | G9: 19.445009 | H9: 18.712775 | I9: 18.274854 | J9: 16.713615 | K9: 15.964862 | L9: 17.250424 | M9: 19.044257 | N9: 19.514713 | O9: 17.417721 | P9: 17.978821 | Q9: 22.490763 | R9: 17.973734 | S9: 17.179828 | T9: 17.208331
A10: Pakistan | B10: PAK | C10: Foreign direct investment, net inflows (BoP, current US$) | D10: BX.KLT.DINV.CD.WD | E10: 2022000000 | F10: 1326000000 | G10: 859000000 | H10: 1333000000 | I10: 1887000000 | J10: 1673000000 | K10: 2576000000 | L10: 2496000000 | M10: 1737000000 | N10: 2234000000 | O10: 2057000000 | P10: 2147000000 | Q10: 1462000000 | R10: 2048000000 | S10: 2665000000 | T10: 1852000000
A11: Pakistan | B11: PAK | C11: Population, total | D11: SP.POP.TOTL | E11: 199239047 | F11: 203746065 | G11: 207667125 | H11: 211073978 | I11: 214264647 | J11: 217290883 | K11: 220138869 | L11: 223273967 | M11: 226928892 | N11: 230800899 | O11: 235001746 | P11: 239477801 | Q11: 243700667 | R11: 247504495 | S11: 251269164 | T11: 255219554
A12: India | B12: IND | C12: GDP (current US$) | D12: NY.GDP.MKTP.CD | E12: 1.6756155e+12 | F12: 1.8230518e+12 | G12: 1.8276376e+12 | H12: 1.8567215e+12 | I12: 2.0391265e+12 | J12: 2.1035884e+12 | K12: 2.2947969e+12 | L12: 2.6514743e+12 | M12: 2.7029296e+12 | N12: 2.8356063e+12 | O12: 2.6748516e+12 | P12: 3.1672706e+12 | Q12: 3.2499385e+12 | R12: 3.500906e+12 | S12: 3.7608135e+12 | T12: 3.9560671e+12
A13: India | B13: IND | C13: GDP growth (annual %) | D13: NY.GDP.MKTP.KD.ZG | E13: 8.4975847 | F13: 5.2413162 | G13: 5.4563876 | H13: 6.3861064 | I13: 7.4102276 | J13: 7.9962538 | K13: 8.2563055 | L13: 6.7953834 | M13: 6.4538513 | N13: 3.8714369 | O13: -5.7777247 | P13: 9.6895925 | Q13: 7.609365 | R13: 7.2102246 | S13: 7.0992789 | T13: 7.5666618
A14: India | B14: IND | C14: Inflation, consumer prices (annual %) | D14: FP.CPI.TOTL.ZG | E14: 11.98939 | F14: 8.9117934 | G14: 9.4789969 | H14: 10.017878 | I14: 6.6656567 | J14: 4.9069734 | K14: 4.9482163 | L14: 3.3281734 | M14: 3.9388265 | N14: 3.7295057 | O14: 6.6234368 | P14: 5.1314075 | Q14: 6.6990341 | R14: 5.6491432 | S14: 4.9530355 | T14: 2.3988495
A15: India | B15: IND | C15: Unemployment, total (% of total labor force) (modeled ILO estimate) | D15: SL.UEM.TOTL.ZS | E15: 7.631 | F15: 7.609 | G15: 7.645 | H15: 7.678 | I15: 7.656 | J15: 7.629 | K15: 7.611 | L15: 7.626 | M15: 7.652 | N15: 6.51 | O15: 7.859 | P15: 6.38 | Q15: 4.822 | R15: 4.172 | S15: 4.173 | T15: 4.219
A16: India | B16: IND | C16: Lending interest rate (%) | D16: FR.INR.LEND | E16: 8.33335 | F16: 10.166667 | G16: 10.604167 | H16: 10.291667 | I16: 10.25 | J16: 10.008333 | K16: 9.6725 | L16: 9.5083333 | M16: 9.4541667 | N16: 9.46625 | O16: 9.15 | P16: 8.6983333 | Q16: 8.5671429 | R16: .. | S16: .. | T16: ..
A17: India | B17: IND | C17: Official exchange rate (LCU per US$, period average) | D17: PA.NUS.FCRF | E17: 45.725812 | F17: 46.670467 | G17: 53.437233 | H17: 58.597845 | I17: 61.029514 | J17: 64.151944 | K17: 67.195313 | L17: 65.121569 | M17: 68.389467 | N17: 70.420341 | O17: 74.099567 | P17: 73.918013 | Q17: 78.604491 | R17: 82.599276 | S17: 83.669282 | T17: 87.158448
A18: India | B18: IND | C18: Exports of goods and services (% of GDP) | D18: NE.EXP.GNFS.ZS | E18: 22.400933 | F18: 24.540411 | G18: 24.534431 | H18: 25.430861 | I18: 22.967963 | J18: 19.813189 | K18: 19.158235 | L18: 18.791765 | M18: 19.927829 | N18: 18.664265 | O18: 18.682477 | P18: 21.399158 | Q18: 24.040172 | R18: 22.354802 | S18: 22.063982 | T18: 22.263041
A19: India | B19: IND | C19: Imports of goods and services (% of GDP) | D19: NE.IMP.GNFS.ZS | E19: 26.854273 | F19: 31.083469 | G19: 31.259291 | H19: 28.413271 | I19: 25.954223 | J19: 22.109725 | K19: 20.924251 | L19: 21.950732 | M19: 23.689141 | N19: 21.241139 | O19: 19.075628 | P19: 24.02393 | Q19: 26.657767 | R19: 23.96815 | S19: 23.852709 | T19: 24.00516
A20: India | B20: IND | C20: Foreign direct investment, net inflows (BoP, current US$) | D20: BX.KLT.DINV.CD.WD | E20: 2.7396885e+10 | F20: 3.6498655e+10 | G20: 2.3995685e+10 | H20: 2.8153031e+10 | I20: 3.4576644e+10 | J20: 4.4009492e+10 | K20: 4.4458572e+10 | L20: 3.9966091e+10 | M20: 4.2117451e+10 | N20: 5.0610647e+10 | O20: 6.4362365e+10 | P20: 4.4727278e+10 | Q20: 4.9940258e+10 | R20: 2.8086194e+10 | S20: 2.7139853e+10 | T20: 3.9097233e+10
A21: India | B21: IND | C21: Population, total | D21: SP.POP.TOTL | E21: 1243481564 | F21: 1261224954 | G21: 1278674502 | H21: 1295829511 | I21: 1312277191 | J21: 1328024498 | K21: 1343944296 | L21: 1359657400 | M21: 1374659064 | N21: 1389030312 | O21: 1402617695 | P21: 1414203896 | Q21: 1425423212 | R21: 1438069596 | S21: 1450935791 | T21: 1463865525
A22: China | B22: CHN | C22: GDP (current US$) | D22: NY.GDP.MKTP.CD | E22: 6.1925649e+12 | F22: 7.6717572e+12 | G22: 8.6736647e+12 | H22: 9.7431242e+12 | I22: 1.0674533e+13 | J22: 1.1280815e+13 | K22: 1.1456024e+13 | L22: 1.2537559e+13 | M22: 1.4147766e+13 | N22: 1.4560167e+13 | O22: 1.4996414e+13 | P22: 1.8201699e+13 | Q22: 1.8316765e+13 | R22: 1.8270357e+13 | S22: 1.8729668e+13 | T22: 1.9498039e+13
A23: China | B23: CHN | C23: GDP growth (annual %) | D23: NY.GDP.MKTP.KD.ZG | E23: 10.59169 | F23: 9.4620525 | G23: 7.8578201 | H23: 7.7784295 | I23: 7.4610074 | J23: 6.9816226 | K23: 6.7736887 | L23: 6.8912392 | M23: 6.7578061 | N23: 6.0673781 | O23: 2.3395039 | P23: 8.5703841 | Q23: 3.1338544 | R23: 5.4160033 | S23: 4.9583038 | T23: 4.9599489
A24: China | B24: CHN | C24: Inflation, consumer prices (annual %) | D24: FP.CPI.TOTL.ZG | E24: 3.1753248 | F24: 5.5538989 | G24: 2.6195243 | H24: 2.62105 | I24: 1.9216416 | J24: 1.4370238 | K24: 2.0000018 | L24: 1.593136 | M24: 2.0747904 | N24: 2.8992342 | O24: 2.4194219 | P24: 0.98101514 | Q24: 1.9735756 | R24: 0.23483683 | S24: 0.21812894 | T24: 0.059564692
A25: China | B25: CHN | C25: Unemployment, total (% of total labor force) (modeled ILO estimate) | D25: SL.UEM.TOTL.ZS | E25: 4.53 | F25: 4.55 | G25: 4.58 | H25: 4.6 | I25: 4.63 | J25: 4.65 | K25: 4.56 | L25: 4.47 | M25: 4.31 | N25: 4.56 | O25: 5 | P25: 4.55 | Q25: 4.98 | R25: 4.67 | S25: 4.59 | T25: 4.615
A26: China | B26: CHN | C26: Lending interest rate (%) | D26: FR.INR.LEND | E26: 5.81 | F26: 6.56 | G26: 6 | H26: 6 | I26: 5.6 | J26: 4.35 | K26: 4.35 | L26: 4.35 | M26: 4.35 | N26: 4.35 | O26: 4.35 | P26: 4.35 | Q26: 4.35 | R26: 4.35 | S26: 4.35 | T26: ..
A27: China | B27: CHN | C27: Official exchange rate (LCU per US$, period average) | D27: PA.NUS.FCRF | E27: 6.770269 | F27: 6.4614613 | G27: 6.3123328 | H27: 6.1957583 | I27: 6.1434341 | J27: 6.2274887 | K27: 6.6444778 | L27: 6.7587551 | M27: 6.6159572 | N27: 6.908385 | O27: 6.9007673 | P27: 6.4489752 | Q27: 6.7371581 | R27: 7.0839984 | S27: 7.1974911 | T27: 7.1898474
A28: China | B28: CHN | C28: Exports of goods and services (% of GDP) | D28: NE.EXP.GNFS.ZS | E28: 26.722745 | F28: 26.151883 | G28: 25.076704 | H28: 24.163343 | I28: 23.071977 | J28: 20.939064 | K28: 19.203651 | L28: 19.33563 | M28: 18.77052 | N28: 18.139822 | O28: 18.269601 | P28: 19.435056 | Q28: 20.227756 | R28: 19.402309 | S28: 20.442828 | T28: 21.071198
A29: China | B29: CHN | C29: Imports of goods and services (% of GDP) | D29: NE.IMP.GNFS.ZS | E29: 23.131327 | F29: 23.793944 | G29: 22.403509 | H29: 21.752698 | I29: 20.99648 | J29: 17.758121 | K29: 16.97352 | L29: 17.615222 | M29: 18.123865 | N29: 17.314613 | O29: 16.068177 | P29: 17.207823 | Q29: 17.2848 | R29: 17.336841 | S29: 17.513232 | T29: 16.88519
A30: China | B30: CHN | C30: Foreign direct investment, net inflows (BoP, current US$) | D30: BX.KLT.DINV.CD.WD | E30: 2.4370343e+11 | F30: 2.8007222e+11 | G30: 2.4121387e+11 | H30: 2.9092843e+11 | I30: 2.6809718e+11 | J30: 2.4248933e+11 | K30: 1.7474958e+11 | L30: 1.6608376e+11 | M30: 2.3536505e+11 | N30: 1.8716982e+11 | O30: 2.5309562e+11 | P30: 3.4407498e+11 | Q30: 1.9020379e+11 | R30: 5.1338077e+10 | S30: 4.2646542e+10 | T30: 7.9979866e+10
A31: China | B31: CHN | C31: Population, total | D31: SP.POP.TOTL | E31: 1337705000 | F31: 1345035000 | G31: 1354190000 | H31: 1363240000 | I31: 1371860000 | J31: 1379860000 | K31: 1387790000 | L31: 1396215000 | M31: 1402760000 | N31: 1407745000 | O31: 1411100000 | P31: 1412360000 | Q31: 1412175000 | R31: 1410710000 | S31: 1408975000 | T31: 1406585000
A32: Japan | B32: JPN | C32: GDP (current US$) | D32: NY.GDP.MKTP.CD | E32: 5.8115781e+12 | F32: 6.2794226e+12 | G32: 6.3338039e+12 | H32: 5.272297e+12 | I32: 4.9857633e+12 | J32: 4.5344386e+12 | K32: 5.1103574e+12 | L32: 5.0382316e+12 | M32: 5.1542937e+12 | N32: 5.245755e+12 | O32: 5.1891975e+12 | P32: 5.2259335e+12 | Q32: 4.4479762e+12 | R32: 4.3848543e+12 | S32: 4.1900082e+12 | T32: 4.435163e+12
A33: Japan | B33: JPN | C33: GDP growth (annual %) | D33: NY.GDP.MKTP.KD.ZG | E33: 4.1364559 | F33: -0.20035785 | G33: 1.6489345 | H33: 1.9972765 | I33: 0.90591549 | J33: 1.7999774 | K33: 0.7049865 | L33: 1.6234506 | M33: 0.83414385 | N33: -0.30849692 | O33: -4.2832794 | P33: 3.5641953 | Q33: 1.3316475 | R33: 0.7207853 | S33: -0.24008424 | T33: 1.1931129
A34: Japan | B34: JPN | C34: Inflation, consumer prices (annual %) | D34: FP.CPI.TOTL.ZG | E34: -0.72824321 | F34: -0.27245562 | G34: -0.04406451 | H34: 0.33503791 | I34: 2.7592267 | J34: 0.79527963 | K34: -0.12725884 | L34: 0.4841998 | M34: 0.9890946 | N34: 0.46877616 | O34: -0.024995834 | P34: -0.23335278 | Q34: 2.4977028 | R34: 3.2681337 | S34: 2.7385368 | T34: 3.1725303
A35: Japan | B35: JPN | C35: Unemployment, total (% of total labor force) (modeled ILO estimate) | D35: SL.UEM.TOTL.ZS | E35: 5.102 | F35: 4.55 | G35: 4.358 | H35: 4.038 | I35: 3.589 | J35: 3.385 | K35: 3.132 | L35: 2.822 | M35: 2.467 | N35: 2.351 | O35: 2.809 | P35: 2.808 | Q35: 2.614 | R35: 2.6 | S35: 2.5 | T35: 2.451
A36: Japan | B36: JPN | C36: Lending interest rate (%) | D36: FR.INR.LEND | E36: 1.5983333 | F36: 1.5009167 | G36: 1.4075 | H36: 1.30375 | I36: 1.2191667 | J36: 1.1428333 | K36: 1.04475 | L36: 0.994 | M36: .. | N36: .. | O36: .. | P36: .. | Q36: .. | R36: .. | S36: .. | T36: ..
A37: Japan | B37: JPN | C37: Official exchange rate (LCU per US$, period average) | D37: PA.NUS.FCRF | E37: 87.779875 | F37: 79.80702 | G37: 79.790455 | H37: 97.595658 | I37: 105.94478 | J37: 121.04403 | K37: 108.7929 | L37: 112.16614 | M37: 110.42318 | N37: 109.00967 | O37: 106.77458 | P37: 109.75432 | Q37: 131.49814 | R37: 140.4911 | S37: 151.36629 | T37: 149.65793
A38: Japan | B38: JPN | C38: Exports of goods and services (% of GDP) | D38: NE.EXP.GNFS.ZS | E38: 14.782738 | F38: 14.664526 | G38: 14.273915 | H38: 15.603709 | I38: 17.107863 | J38: 17.09211 | K38: 15.722396 | L38: 17.215825 | M38: 17.911143 | N38: 17.037797 | O38: 15.12869 | P38: 17.461985 | Q38: 20.647867 | R38: 21.05931 | S38: 21.979909 | T38: ..
A39: Japan | B39: JPN | C39: Imports of goods and services (% of GDP) | D39: NE.IMP.GNFS.ZS | E39: 13.457277 | F39: 15.306859 | G39: 15.900384 | H39: 17.98766 | I39: 19.656462 | J39: 17.635521 | K39: 14.933883 | L39: 16.473008 | M39: 17.892431 | N39: 17.3205 | O39: 15.390532 | P39: 17.963407 | Q39: 24.212764 | R39: 22.535773 | S39: 22.873029 | T39: ..
A40: Japan | B40: JPN | C40: Foreign direct investment, net inflows (BoP, current US$) | D40: BX.KLT.DINV.CD.WD | E40: 7.4409793e+09 | F40: -8.5071704e+08 | G40: 5.4696269e+08 | H40: 1.0648442e+10 | I40: 1.9752249e+10 | J40: 5.2522184e+09 | K40: 4.0954181e+10 | L40: 1.8802251e+10 | M40: 2.5289368e+10 | N40: 3.9960544e+10 | O40: 6.2584719e+10 | P40: 3.5027164e+10 | Q40: 4.8153833e+10 | R40: 2.0007989e+10 | S40: 1.8874094e+10 | T40: 4.5805721e+10
...

Sheet Series - Metadata
A1: Code | B1: License Type | C1: Indicator Name | D1: Long definition | E1: Source | F1: Topic | G1: Dataset | H1: Unit of measure | I1: Periodicity | J1: Reference period | K1: Aggregation method | L1: Statistical concept and methodology | M1: Development relevance | N1: Limitations and exceptions | O1: Other notes | P1: License URL
A2: NY.GDP.MKTP.CD | B2: CC BY-4.0 | C2: GDP (current US$) | D2: Gross domestic product is the total income earned through the production of goods and services in an economic territory during an accounting period. It can be measured in three different ways: using either the expenditure approach, the income approach, or the production approach. This indicator is expressed in current prices, meaning no adjustment has been made to account for price changes over time. This indicator is expressed in United States dollars. | E2: Country official statistics, National Statistical Organizations and/or Central Banks; National Accounts data files, Organisation for Economic Co-operation and Development (OECD); Staff estimates, World Bank (WB) | F2: Economic Policy & Debt: National accounts: US$ at current prices: Aggregate indicators | G2: WB_WDI | H2: current US$ | I2: Annual | J2: 1960-2025 | K2: Gap-filled total | L2: Methodology: National accounts are compiled in accordance with international standards: System of National Accounts, 2008 or 1993 versions. Specific information on how countries compile their national accounts can be found on the IMF website: https://dsbb.imf.org/ Statistical concept(s): The conceptual elements of the SNA (System of National Accounts) measure what takes place in the economy, between which agents, and for what purpose. At the heart of the SNA is the production of goods and services. These may be used for consumption in the period to which the accounts relate or may be accumulated for use in a later period. In simple terms, the amount of value added generated by production represents GDP. The income corresponding to GDP is distributed to the various agents or groups of agents as income and it is the process of distributing and redistributing income that allows one agent to consume the goods and services produced by another agent or to acquire goods and services for later consumption. The way in which the SNA captures this pattern of economic flows is to identify the activities concerned by recognizing the institutional units in the economy and by specifying the structure of accounts capturing the transactions relevant to one stage or another of the process by which goods and services are produced and ultimately consumed. | M2: This indicator is related to the national accounts, which are critical for understanding and managing a country's economy. They provide a framework for the analysis of economic performance. National accounts are the basis for estimating the Gross Domestic Product (GDP) and Gross National Income (GNI), which are the most widely used indicator of economic performance. They are essential for government policymakers, providing the data needed to design and assess fiscal and monetary policies; and are also used by businesses and investors to assess the economic climate and make investment decisions. NAS enable comparison between economies, which is crucial for international trade, investment decisions, and economic competitiveness. More specifically, this indicator is related to national accounts aggregates. Gross Domestic Product (GDP), Gross National Income (GNI), and other aggregates provide a snapshot of the size and health of an economy by measuring the total economic activity within a country. They can thus be used by policymakers to design and implement economic policies, as they reflect the overall economic performance and can indicate the need for intervention in certain areas. Aggregates also allow for comparisons between different economies, which can be useful for trade negotiations, investment decisions, and economic benchmarking. By examining aggregates over time, economists and analysts can identify trends, cycles, and potential areas of concern within an economy, and investors can use national accounts aggregates to assess the potential risks and returns of investing in a particular country. Overall, national accounts aggregates are fundamental tools for economic analysis, policy formulation, and decision-making at both the national and international levels. | N2: Gross domestic product (GDP), though widely tracked, may not always be the most relevant summary of aggregated economic performance for all economies, especially when production occurs at the expense of consuming capital stock. While GDP estimates based on the production approach are generally more reliable than estimates compiled from the income or expenditure side, different countries use different definitions, methods, and reporting standards. World Bank staff review the quality of national accounts data and sometimes make adjustments to improve consistency with international guidelines. Nevertheless, significant discrepancies remain between international standards and actual practice. Many statistical offices, especially those in developing countries, face severe limitations in the resources, time, training, and budgets required to produce reliable and comprehensive series of national accounts statistics. Among the difficulties faced by compilers of national accounts is the extent of unreported economic activity in the informal or secondary economy. In developing countries a large share of agricultural output is either not exchanged (because it is consumed within the household) or not exchanged for money. | P2: https://datacatalog.worldbank.org/int/public-licenses#cc-by
A3: NY.GDP.MKTP.KD.ZG | B3: CC BY-4.0 | C3: GDP (annual % growth) | D3: Gross domestic product is the total income earned through the production of goods and services in an economic territory during an accounting period. It can be measured in three different ways: using either the expenditure approach, the income approach, or the production approach. This indicator denotes the percentage change over each previous year of the constant price (base year 2015) series in United States dollars. | E3: Country official statistics, National Statistical Organizations and/or Central Banks; National Accounts data files, Organisation for Economic Co-operation and Development (OECD); Staff estimates, World Bank (WB) | F3: Economic Policy & Debt: National accounts: Growth rates | G3: WB_WDI | H3: % | I3: Annual | J3: 1961-2025 | K3: Weighted average | L3: Methodology: National accounts are compiled in accordance with international standards: System of National Accounts, 2008 or 1993 versions. Specific information on how countries compile their national accounts can be found on the IMF website: https://dsbb.imf.org/ Statistical concept(s): The conceptual elements of the SNA (System of National Accounts) measure what takes place in the economy, between which agents, and for what purpose. At the heart of the SNA is the production of goods and services. These may be used for consumption in the period to which the accounts relate or may be accumulated for use in a later period. In simple terms, the amount of value added generated by production represents GDP. The income corresponding to GDP is distributed to the various agents or groups of agents as income and it is the process of distributing and redistributing income that allows one agent to consume the goods and services produced by another agent or to acquire goods and services for later consumption. The way in which the SNA captures this pattern of economic flows is to identify the activities concerned by recognizing the institutional units in the economy and by specifying the structure of accounts capturing the transactions relevant to one stage or another of the process by which goods and services are produced and ultimately consumed. | M3: This indicator is related to the national accounts, which are critical for understanding and managing a country's economy. They provide a framework for the analysis of economic performance. National accounts are the basis for estimating the Gross Domestic Product (GDP) and Gross National Income (GNI), which are the most widely used indicator of economic performance. They are essential for government policymakers, providing the data needed to design and assess fiscal and monetary policies; and are also used by businesses and investors to assess the economic climate and make investment decisions. NAS enable comparison between economies, which is crucial for international trade, investment decisions, and economic competitiveness. More specifically, this indicator is related to national accounts aggregates. Gross Domestic Product (GDP), Gross National Income (GNI), and other aggregates provide a snapshot of the size and health of an economy by measuring the total economic activity within a country. They can thus be used by policymakers to design and implement economic policies, as they reflect the overall economic performance and can indicate the need for intervention in certain areas. Aggregates also allow for comparisons between different economies, which can be useful for trade negotiations, investment decisions, and economic benchmarking. By examining aggregates over time, economists and analysts can identify trends, cycles, and potential areas of concern within an economy, and investors can use national accounts aggregates to assess the potential risks and returns of investing in a particular country. Overall, national accounts aggregates are fundamental tools for economic analysis, policy formulation, and decision-making at both the national and international levels. | N3: Each industry's contribution to growth in the economy's output is measured by growth in the industry's value added. In principle, value added in constant prices can be estimated by measuring the quantity of goods and services produced in a period, valuing them at an agreed set of base year prices, and subtracting the cost of intermediate inputs, also in constant prices. This double-deflation method requires detailed information on the structure of prices of inputs and outputs. In many industries, however, value added is extrapolated from the base year using single volume indexes of outputs or, less commonly, inputs. Particularly in the services industries, including most of government, value added in constant prices is often imputed from labor inputs, such as real wages or number of employees. In the absence of well defined measures of output, measuring the growth of services remains difficult. Moreover, technical progress can lead to improvements in production processes and in the quality of goods and services that, if not properly accounted for, can distort measures of value added and thus of growth. When inputs are used to estimate output, as for nonmarket services, unmeasured technical progress leads to underestimates of the volume of output. Similarly, unmeasured improvements in quality lead to underestimates of the value of output and value added. The result can be underestimates of growth and productivity improvement and overestimates of inflation. Informal economic activities pose a particular measurement problem, especially in developing countries, where much economic activity is unrecorded. A complete picture of the economy requires estimating household outputs produced for home use, sales in informal markets, barter exchanges, and illicit or deliberately unreported activities. The consistency and completeness of such estimates depend on the skill and methods of the compiling statisticians. Rebasing of national accounts can alter the measured growth rate of an economy and lead to breaks in series that affect the consistency of data over time. When countries rebase their national accounts, they update the weights assigned to various components to better reflect current patterns of production or uses of output. The new base year should represent normal operation of the economy - it should be a year without major shocks or distortions. Some developing countries have not rebased their national accounts for many years. Using an old base year can be misleading because implicit price and volume weights become progressively less relevant and useful. To obtain comparable series of constant price data for computing aggregates, the World Bank rescales GDP and value added by industrial origin to a common reference year. Because rescaling changes the implicit weights used in forming regional and income group aggregates, aggregate growth rates are not comparable with those from earlier editions with different base years. Rescaling may result in a discrepancy between the rescaled GDP and the sum of the rescaled components. To avoid distortions in the growth rates, the discrepancy is left unallocated. As a result, the weighted average of the growth rates of the components generally does not equal the GDP growth rate. | P3: https://datacatalog.worldbank.org/int/public-licenses#cc-by
A4: FP.CPI.TOTL.ZG | B4: CC BY-4.0 | C4: Inflation, consumer prices (annual % growth) | D4: Inflation as measured by the consumer price index reflects the annual percentage change in the cost to the average consumer of acquiring a basket of goods and services that may be fixed or changed at specified intervals, such as yearly. | E4: International Financial Statistics database, International Monetary Fund (IMF) | F4: Financial Sector: Exchange rates & prices | G4: WB_WDI | H4: % | I4: Annual | J4: 1960-2025 | K4: Median | L4: Methodology: Consumer Prices Indices are compiled in accordance with international standards: Consumer Price Index Manual, 2020 or 2004 version. Specific information on how countries compile their CPI statistics can be found on the IMF website: https://dsbb.imf.org/ Statistical concept(s): The conceptual basis of a consumer price index series is to measure the rate at which prices of consumption goods and services are changing from one period to another. | M4: A general and continuing increase in an economy’s price level is called inflation. The increase in the average prices of goods and services in the economy should be distinguished from a change in the relative prices of individual goods and services. Generally accompanying an overall increase in the price level is a change in the structure of relative prices, but it is only the average increase, not the relative price changes, that constitutes inflation. A commonly used measure of inflation is the consumer price index, which measures the prices of a representative basket of goods and services purchased by a typical household. The consumer price index is usually calculated on the basis of periodic surveys of consumer prices. Other price indices are derived implicitly from indexes of current and constant price series. | P4: https://datacatalog.worldbank.org/int/public-licenses#cc-by
A5: SL.UEM.TOTL.ZS | B5: CC BY-4.0 | C5: Unemployment, total (% of total labor force) (modeled ILO estimate) | D5: Unemployment refers to the share of the labor force that is without work but available for and seeking employment. | E5: ILO Modelled Estimates database (ILOEST), International Labour Organization (ILO), uri: https://ilostat.ilo.org/data/bulk/, publisher: ILOSTAT, type: external database, date accessed: January 17, 2026 | F5: Social Protection & Labor: Unemployment | G5: WB_WDI | H5: % of total labor force | I5: Annual | J5: 1991-2025 | K5: Weighted average | L5: Methodology: The unemployment rate is calculated by expressing the number of unemployed persons as a percentage of the total number of persons in the labor force. The labor force (formerly known as the economically active population) is the sum of the number of persons employed and the number of persons unemployed. The series is part of the "ILO modeled estimates database," including nationally reported observations and imputed data for countries with missing data, primarily to capture regional and global trends with consistent country coverage. Country-reported microdata is based mainly on nationally representative labor force surveys, with other sources (e.g., household surveys and population censuses) considering differences in the data source, the scope of coverage, methodology, and other country-specific factors. Country analysis requires caution where limited nationally reported data are available. A series of models are also applied to impute missing observations and make projections. However, imputed observations are not based on national data, are subject to high uncertainty, and should not be used for country comparisons or rankings. For more information: https://ilostat.ilo.org/resources/concepts-and-definitions/ilo-modelled-estimates/ Statistical concept(s): The unemployed comprise all persons of working age who were: a) without work during the reference period, i.e. were not in paid employment or self-employment; b) currently available for work, i.e. were available for paid employment or self-employment during the reference period; and c) seeking work, i.e. had taken specific steps in a specified recent period to seek paid employment or self-employment. Future starters, that is, persons who did not look for work but have a future labor market stake (made arrangements for a future job start) are also counted as unemployed, as are participants in skills training or retraining schemes within employment promotion programs, who on that basis, were “not in employment”, not “currently available” and did not “seek employment” because they had a job offer to start within a short subsequent period generally not greater than three months. The unemployed also include persons “not in employment” who carried out activities to migrate abroad in order to work for pay or profit but who were still waiting for the opportunity to leave. Employment comprises all persons of working age who during a specified brief period, such as one week or one day, were in the following categories: a) paid employment (whether at work or with a job but not at work); or b) self-employment (whether at work or with an enterprise but not at work). The working-age population is the population above the legal working age, but for statistical purposes it comprises all persons above a specified minimum age threshold for which an inquiry on economic activity is made. To promote international comparability, the working-age population is often defined as all persons aged 15 and older, but this may vary from country to country based on national laws and practices (some countries also apply an upper age limit). | M5: The unemployment rate is a useful measure of the underutilization of the labor supply. It reflects the inability of an economy to generate employment for those persons who want to work but are not doing so, even though they are available for employment and actively seeking work. It is thus seen as an indicator of the efficiency and effectiveness of an economy to absorb its labor force and of the performance of the labor market. Given its usefulness in conveying valuable information on a country’s labor market situation and the fact that it is widely recognized as a headline labor market indicator, it was included as one of the indicators to measure progress towards the achievement of the Sustainable Development Goals (SDG), under Goal 8 (Promote sustained, inclusive and sustainable economic growth, full and productive employment and decent work for all). | N5: While the unemployment rate may be considered the most informative labour market indicator, reflecting the general performance of the labour market and the economy as a whole, it should not be interpreted as a measure of economic hardship or of well-being. When based on the internationally-recommended standards, the unemployment rate simply reflects the proportion of the labour force that does not have a job but is available and actively looking for work. It says nothing about the economic resources of unemployed workers or their family members. Its use should, therefore, be limited to serving as a measurement of the utilization of labour and an indication of the failure to find work. Other measures, including income-related indicators, would be needed to evaluate economic hardship. An additional criticism of the aggregate unemployment measure is that it masks information on the composition of the jobless population and therefore misses out on the particularities of the education level, ethnic origin, socio-economic background, work experience, etc. of the unemployed. Moreover, the unemployment rate says nothing about the type of unemployment – whether it is cyclical and short-term or structural and long-term – which is a critical issue for policy makers in the development of their policy responses, especially given that structural unemployment cannot be addressed by boosting market demand only. | O5: National estimates are also available in the WDI database. Caution should be used when comparing ILO estimates with national estimates. | P5: https://datacatalog.worldbank.org/int/public-licenses#cc-by
A6: FR.INR.LEND | B6: CC BY-4.0 | C6: Lending interest rate (%) | D6: Lending rate is the bank rate that usually meets the short- and medium-term financing needs of the private sector. This rate is normally differentiated according to creditworthiness of borrowers and objectives of financing. The terms and conditions attached to these rates differ by country, however, limiting their comparability. | E6: International Financial Statistics database, International Monetary Fund (IMF) | F6: Financial Sector: Interest rates | G6: WB_WDI | H6: % | I6: Annual | J6: 1960-2025 | L6: Methodology: Monetary and Financial statistics are compiled in accordance with international standards: Monetary and Financial Statistics Manual, 2018 or 2004 versions. Specific information on how countries compile their Monetary and Finance statistics can be found on the IMF website: https://dsbb.imf.org/ Statistical concept(s): The conceptual framework comes from the Monetary and Financial Statistic Manual which outlines the analytical presentation of monetary statistics, which provide critical inputs for monetary policy formulation and monitoring. The statistics covered in this Manual also support the assessment of financial system stability. | M6: Both banking and financial systems enhance growth, the main factor in poverty reduction. At low levels of economic development commercial banks tend to dominate the financial system, while at higher levels domestic stock markets tend to become more active and efficient. The size and mobility of international capital flows make it increasingly important to monitor the strength of financial systems. Robust financial systems can increase economic activity and welfare, but instability can disrupt financial activity and impose widespread costs on the economy. | N6: Countries use a variety of reporting formats, sample designs, interest compounding formulas, averaging methods, and data presentations for indices and other data series on interest rates. The IMF's Monetary and Financial Statistics Manual does not provide guidelines beyond the general recommendation that such data should reflect market prices and effective (rather than nominal) interest rates and should be representative of the financial assets and markets to be covered. For more information, please see http://www.imf.org/external/pubs/ft/mfs/manual/index.htm. | P6: https://datacatalog.worldbank.org/int/public-licenses#cc-by
A7: PA.NUS.FCRF | B7: CC BY-4.0 | C7: Official exchange rate (LCU per US$, period average) | D7: Official exchange rate refers to the exchange rate determined by national authorities or to the rate determined in the legally sanctioned exchange market. This indicator represents the ratio of Local Currency Units relative to United States dollars.This indicator is derived as an average over the reference period. | E7: International Financial Statistics database, International Monetary Fund (IMF) | F7: Financial Sector: Exchange rates & prices | G7: WB_WDI | H7: LCU per US$ | I7: Annual | J7: 1960-2025 | L7: Methodology: The exchange rate is the price of one currency divided by another. Official exchange rates and exchange rate arrangements are established by governments. Other exchange rates recognized by governments include market rates, which are determined largely by legal market forces, and for countries with multiple exchange arrangements, principal rates, secondary rates, and tertiary rates. Annual average exchange rates are derived as the simple average of daily exchange rates for a specified calendar year Statistical concept(s): The exchange rate is the price of one currency in terms of another. Official exchange rates and exchange rate arrangements are established by governments. Other exchange rates recognized by governments include market rates, which are determined largely by legal market forces, and for countries with multiple exchange arrangements, principal rates, secondary rates, and tertiary rates. | M7: In a market-based economy, household, producer, and government choices about resource allocation are influenced by relative prices, including the real exchange rate, real wages, real interest rates, and other prices in the economy. Relative prices also largely reflect these agents' choices. Thus relative prices convey vital information about the interaction of economic agents in an economy and with the rest of the world. | N7: Official or market exchange rates are often used to convert economic statistics in local currencies to a common currency in order to make comparisons across countries. Since market rates reflect at best the relative prices of tradable goods, the volume of goods and services that a U.S. dollar buys in the United States may not correspond to what a U.S. dollar converted to another country's currency at the official exchange rate would buy in that country, particularly when nontradable goods and services account for a significant share of a country's output. An alternative exchange rate - the purchasing power parity (PPP) conversion factor - is preferred because it reflects differences in price levels for both tradable and nontradable goods and services and therefore provides a more meaningful comparison of real output. | P7: https://datacatalog.worldbank.org/int/public-licenses#cc-by
A8: NE.EXP.GNFS.ZS | B8: CC BY-4.0 | C8: Exports of goods and services (% of GDP) | D8: Exports of goods includes changes in the economic ownership of goods from residents of the compiling economy to non-residents, irrespective of physical movement of goods across national borders. Exports of services includes services provided by residents to non-residents. This indicator is expressed as a percentage of Gross Domestic Product (GDP) which is the total income earned through the production of goods and services in an economic territory during an accounting period. | E8: Country official statistics, National Statistical Offices (NSOs); National Accounts data files, Central Banks; Staff estimates, World Bank (WB) | F8: Economic Policy & Debt: National accounts: Shares of GDP & other | G8: WB_WDI | H8: % | I8: Annual | J8: 1960-2025 | K8: Weighted average | L8: Methodology: National accounts are compiled in accordance with international standards: System of National Accounts, 2008 or 1993 versions. Specific information on how countries compile their national accounts can be found on the IMF website: https://dsbb.imf.org/ Statistical concept(s): The conceptual elements of the SNA (System of National Accounts) measure what takes place in the economy, between which agents, and for what purpose. At the heart of the SNA is the production of goods and services. These may be used for consumption in the period to which the accounts relate or may be accumulated for use in a later period. In simple terms, the amount of value added generated by production represents GDP. The income corresponding to GDP is distributed to the various agents or groups of agents as income and it is the process of distributing and redistributing income that allows one agent to consume the goods and services produced by another agent or to acquire goods and services for later consumption. The way in which the SNA captures this pattern of economic flows is to identify the activities concerned by recognizing the institutional units in the economy and by specifying the structure of accounts capturing the transactions relevant to one stage or another of the process by which goods and services are produced and ultimately consumed. | M8: This indicator is related to the national accounts, which are critical for understanding and managing a country's economy. They provide a framework for the analysis of economic performance. National accounts are the basis for estimating the Gross Domestic Product (GDP) and Gross National Income (GNI), which are the most widely used indicators of economic performance. They are essential for government policymakers, providing the data needed to design and assess fiscal and monetary policies; and are also used by businesses and investors to assess the economic climate and make investment decisions. NAS enable comparison between economies, which is crucial for international trade, investment decisions, and economic competitiveness. More specifically, this indicator is related to the expenditure approach used to calculate GDP, which focuses on the total amount of spending on final goods and services within an economy over a specific period. Unlike the production approach, which looks at the supply side by summing the value of output produced by all sectors, the expenditure approach looks at the demand side by summing all expenditures. This demand-side analysis provides insights into the spending behaviors of different sectors, including households, businesses, the government, and foreign entities. Also, by breaking down expenditures into categories like consumption, investment, government spending, and net exports, it helps identify which components are driving or hindering economic growth. This approach can thus be used to assess the effectiveness of fiscal and monetary policies. Overall, the expenditure approach is crucial for understanding the dynamics of an economy, guiding policy decisions, and providing a comprehensive view of economic activity from the perspective of total spending. | N8: Because policymakers have tended to focus on fostering the growth of output, and because data on production are easier to collect than data on spending, many countries generate their primary estimate of GDP using the production approach. Moreover, many countries do not estimate all the components of national expenditures but instead derive some of the main aggregates indirectly using GDP (based on the production approach) as the control total. Data on exports and imports are compiled from customs reports and balance of payments data. Although the data from the payments side provide reasonably reliable records of cross-border transactions, they may not adhere strictly to the appropriate definitions of valuation and timing used in the balance of payments or correspond to the change-of ownership criterion. This issue has assumed greater significance with the increasing globalization of international business. Neither customs nor balance of payments data usually capture the illegal transactions that occur in many countries. Goods carried by travelers across borders in legal but unreported shuttle trade may further distort trade statistics. | P8: https://datacatalog.worldbank.org/int/public-licenses#cc-by
A9: NE.IMP.GNFS.ZS | B9: CC BY-4.0 | C9: Imports of goods and services (% of GDP) | D9: Imports of goods includes change in the economic ownership of goods from non-residents to residents of the compiling economy, irrespective of physical movement of goods across national borders. Imports of services includes services provided by non-residents to residents. This indicator is expressed as a percentage of Gross Domestic Product (GDP) which is the total income earned through the production of goods and services in an economic territory during an accounting period. | E9: Country official statistics, National Statistical Offices (NSOs); National Accounts data files, Central Banks; Staff estimates, World Bank (WB) | F9: Economic Policy & Debt: National accounts: Shares of GDP & other | G9: WB_WDI | H9: % | I9: Annual | J9: 1960-2025 | K9: Weighted average | L9: Methodology: National accounts are compiled in accordance with international standards: System of National Accounts, 2008 or 1993 versions. Specific information on how countries compile their national accounts can be found on the IMF website: https://dsbb.imf.org/ Statistical concept(s): The conceptual elements of the SNA (System of National Accounts) measure what takes place in the economy, between which agents, and for what purpose. At the heart of the SNA is the production of goods and services. These may be used for consumption in the period to which the accounts relate or may be accumulated for use in a later period. In simple terms, the amount of value added generated by production represents GDP. The income corresponding to GDP is distributed to the various agents or groups of agents as income and it is the process of distributing and redistributing income that allows one agent to consume the goods and services produced by another agent or to acquire goods and services for later consumption. The way in which the SNA captures this pattern of economic flows is to identify the activities concerned by recognizing the institutional units in the economy and by specifying the structure of accounts capturing the transactions relevant to one stage or another of the process by which goods and services are produced and ultimately consumed. | M9: This indicator is related to the national accounts, which are critical for understanding and managing a country's economy. They provide a framework for the analysis of economic performance. National accounts are the basis for estimating the Gross Domestic Product (GDP) and Gross National Income (GNI), which are the most widely used indicator of economic performance. They are essential for government policymakers, providing the data needed to design and assess fiscal and monetary policies; and are also used by businesses and investors to assess the economic climate and make investment decisions. NAS enable comparison between economies, which is crucial for international trade, investment decisions, and economic competitiveness. More specifically, this indicator is related to the expenditure approach used to calculate GDP, which focuses on the total amount of spending on final goods and services within an economy over a specific period. Unlike the production approach, which looks at the supply side by summing the value of output produced by all sectors, the expenditure approach looks at the demand side by summing all expenditures. This demand-side analysis provides insights into the spending behaviors of different sectors, including households, businesses, the government, and foreign entities. Also, by breaking down expenditures into categories like consumption, investment, government spending, and net exports, it helps identify which components are driving or hindering economic growth. This approach can thus be used to assess the effectiveness of fiscal and monetary policies. Overall, the expenditure approach is crucial for understanding the dynamics of an economy, guiding policy decisions, and providing a comprehensive view of economic activity from the perspective of total spending. | N9: Because policymakers have tended to focus on fostering the growth of output, and because data on production are easier to collect than data on spending, many countries generate their primary estimate of GDP using the production approach. Moreover, many countries do not estimate all the components of national expenditures but instead derive some of the main aggregates indirectly using GDP (based on the production approach) as the control total. Data on exports and imports are compiled from customs reports and balance of payments data. Although the data from the payments side provide reasonably reliable records of cross-border transactions, they may not adhere strictly to the appropriate definitions of valuation and timing used in the balance of payments or corresponds to the change-of ownership criterion. This issue has assumed greater significance with the increasing globalization of international business. Neither customs nor balance of payments data usually capture the illegal transactions that occur in many countries. Goods carried by travelers across borders in legal but unreported shuttle trade may further distort trade statistics. | P9: https://datacatalog.worldbank.org/int/public-licenses#cc-by
A10: BX.KLT.DINV.CD.WD | B10: CC BY-4.0 | C10: Foreign direct investment, net inflows (BoP, current US$) | D10: Foreign direct investment refers to direct investment equity flows in the reporting economy. It is the sum of equity capital, reinvestment of earnings, and other capital. Direct investment is a category of cross-border investment associated with a resident in one economy having control or a significant degree of influence on the management of an enterprise that is resident in another economy. Ownership of 10 percent or more of the ordinary shares of voting stock is the criterion for determining the existence of a direct investment relationship. Data are in current U.S. dollars. | E10: Balance of Payments database, International Monetary Fund (IMF), note: International Monetary Fund, Balance of Payments database, supplemented by data from the United Nations Conference on Trade and Development and official national sources.; UN Conference on Trade and Development (UNCTAD); Official national sources | F10: Economic Policy & Debt: Balance of payments: Capital & financial account | G10: WB_WDI | I10: Annual | J10: 1970-2025 | K10: Sum | L10: Methodology: Data on equity flows are based on balance of payments data reported by the International Monetary Fund (IMF). Foreign direct investment (FDI) data are supplemented by the World Bank staff estimates using data from the United Nations Conference on Trade and Development (UNCTAD) and official national sources. The internationally accepted definition of FDI (from the sixth edition of the IMF's Balance of Payments Manual [2009]), includes the following components: equity investment, including investment associated with equity that gives rise to control or influence; investment in indirectly influenced or controlled enterprises; investment in fellow enterprises; debt (except selected debt); and reverse investment. The Framework for Direct Investment Relationships provides criteria for determining whether cross-border ownership results in a direct investment relationship, based on control and influence. Distinguished from other kinds of international investment, FDI is made to establish a lasting interest in or effective management control over an enterprise in another country. A lasting interest in an investment enterprise typically involves establishing warehouses, manufacturing facilities, and other permanent or long-term organizations abroad. Direct investments may take the form of greenfield investment, where the investor starts a new venture in a foreign country by constructing new operational facilities; joint venture, where the investor enters into a partnership agreement with a company abroad to establish a new enterprise; or merger and acquisition, where the investor acquires an existing enterprise abroad. The IMF suggests that investments should account for at least 10 percent of voting stock to be counted as FDI. In practice many countries set a higher threshold. Many countries fail to report reinvested earnings, and the definition of long-term loans differs among countries. BoP refers to Balance of Payments. | M10: Private financial flows - equity and debt - account for the bulk of development finance. Equity flows comprise foreign direct investment (FDI) and portfolio equity. Debt flows are financing raised through bond issuance, bank lending, and supplier credits. | N10: FDI data do not give a complete picture of international investment in an economy. Balance of payments data on FDI do not include capital raised locally, an important source of investment financing in some developing countries. In addition, FDI data omit nonequity cross-border transactions such as intra-unit flows of goods and services. The volume of global private financial flows reported by the World Bank generally differs from that reported by other sources because of differences in sources, classification of economies, and method used to adjust and disaggregate reported information. In addition, particularly for debt financing, differences may also reflect how some installments of the transactions and certain offshore issuances are treated. Data on equity flows are shown for all countries for which data are available. | O10: Note: Data starting from 2005 are based on the sixth edition of the IMF's Balance of Payments Manual (BPM6). | P10: https://datacatalog.worldbank.org/int/public-licenses#cc-by
